Workbook

Sheet CUISINE SNACK
E2: EMPLOI DU TEMPS CUISINE SNACK WEEK 36
C5: CUISINE SNACK | G5: =+[1]MAINTENANCE!G5 -> LUNDI | H5: 46244
C6: matin | F6: après-midi | I6: soir
B7: Personne | C7: ENTREE-TEST | D7: sortie | E7: durée | F7: entrée | G7: sortie | H7: durée | I7: entrée | J7: sortie | K7: durée | L7: durée total
A8: P477 | B8: ANYAH | C8: 0.25 | D8: 0.5 | E8: 0.5 | F8: 0.5 | G8: 0.58333333 | H8: 0.083333333 | K8: 0 | L8: 0.33333333
A9: P522 | B9: AVOTRA | C9: 0.41666667 | D9: 0.58333333 | E9: =IF(D9>C9,D9-C9,C9-D9) -> 0.16666667 | H9: =IF(G9>F9,G9-F9,F9-G9) -> 0 | I9: 0.75 | J9: 0.91666667 | K9: =IF(J9>I9,J9-I9,I9-J9) -> 0.16666667 | L9: =E9+H9+K9 -> 0.33333333
A10: P543 | B10: AUGUSTIN | E10: =IF(D10>C10,D10-C10,C10-D10) -> 0 | F10: 0.58333333 | G10: 0.75 | H10: =IF(G10>F10,G10-F10,F10-G10) -> 0.16666667 | I10: 0.75 | J10: 0.91666667 | K10: =IF(J10>I10,J10-I10,I10-J10) -> 0.16666667 | L10: =E10+H10+K10 -> 0.33333333
A11: P404 | B11: EDHINO | C11: 0.25 | D11: 0.5 | E11: 0.25 | F11: 0.5 | G11: 0.58333333 | H11: 0.083333333 | K11: 0 | L11: 0.33333333
A12: P472 | B12: HERMANN | C12: 0.25 | D12: 0.5 | E12: =IF(D12>C12,D12-C12,C12-D12) -> 0.25 | F12: 0.5 | G12: 0.58333333 | H12: =IF(G12>F12,G12-F12,F12-G12) -> 0.083333333 | K12: =IF(J12>I12,J12-I12,I12-J12) -> 0 | L12: =E12+H12+K12 -> 0.33333333
A13: P324 | B13: JEAN CHRYS | E13: =IF(D13>C13,D13-C13,C13-D13) -> 0 | F13: 0.58333333 | G13: 0.75 | H13: =IF(G13>F13,G13-F13,F13-G13) -> 0.16666667 | I13: 0.75 | J13: 0.91666667 | K13: =IF(J13>I13,J13-I13,I13-J13) -> 0.16666667 | L13: =E13+H13+K13 -> 0.33333333
A14: P469 | B14: RAVAKA | E14: =IF(D14>C14,D14-C14,C14-D14) -> 0 | H14: =IF(G14>F14,G14-F14,F14-G14) -> 0 | K14: =IF(J14>I14,J14-I14,I14-J14) -> 0 | L14: =E14+H14+K14 -> 0 | M14: REPOS
A15: P268 | B15: ROLAND | C15: 0.25 | D15: 0.5 | E15: =IF(D15>C15,D15-C15,C15-D15) -> 0.25 | F15: 0.5 | G15: 0.58333333 | H15: =IF(G15>F15,G15-F15,F15-G15) -> 0.083333333 | K15: =IF(J15>I15,J15-I15,I15-J15) -> 0 | L15: =E15+H15+K15 -> 0.33333333
A16: P419 | B16: ZIANI | E16: =IF(D16>C16,D16-C16,C16-D16) -> 0 | H16: =IF(G16>F16,G16-F16,F16-G16) -> 0 | K16: =IF(J16>I16,J16-I16,I16-J16) -> 0 | L16: =E16+H16+K16 -> 0 | M16: REPOS
A17: Stagiaire | B17: JIMMY | C17: 0.25 | D17: 0.5 | E17: =IF(D17>C17,D17-C17,C17-D17) -> 0.25 | F17: 0.5 | G17: 0.58333333 | H17: =IF(G17>F17,G17-F17,F17-G17) -> 0.083333333 | K17: =IF(J17>I17,J17-I17,I17-J17) -> 0 | L17: =E17+H17+K17 -> 0.33333333
E18: =SUM(E8:E17) -> 1.4166667 | H18: =SUM(H8:H17) -> 0.75 | K18: =SUM(K8:K17) -> 0.5 | L18: =SUM(L8:L17) -> 2.6666667
C21: CUISINE SNACK | G21: MARDI | H21: =+H5+1 -> 46245
C22: matin | F22: après-midi | I22: soir
B23: Personne | C23: entrée | D23: sortie | E23: durée | F23: entrée | G23: sortie | H23: durée | I23: entrée | J23: sortie | K23: durée | L23: durée total
A24: P477 | B24: ANYAH | C24: 0.25 | D24: 0.5 | E24: =IF(D24>C24,D24-C24,C24-D24) -> 0.25 | F24: 0.5 | G24: 0.58333333 | H24: =IF(G24>F24,G24-F24,F24-G24) -> 0.083333333 | K24: =IF(J24>I24,J24-I24,I24-J24) -> 0 | L24: =E24+H24+K24 -> 0.33333333
A25: P522 | B25: AVOTRA | E25: =IF(D25>C25,D25-C25,C25-D25) -> 0 | H25: =IF(G25>F25,G25-F25,F25-G25) -> 0 | K25: =IF(J25>I25,J25-I25,I25-J25) -> 0 | L25: =E25+H25+K25 -> 0 | M25: REPOS
A26: P543 | B26: AUGUSTIN | E26: =IF(D26>C26,D26-C26,C26-D26) -> 0 | F26: 0.58333333 | G26: 0.75 | H26: =IF(G26>F26,G26-F26,F26-G26) -> 0.16666667 | I26: 0.75 | J26: 0.91666667 | K26: =IF(J26>I26,J26-I26,I26-J26) -> 0.16666667 | L26: =E26+H26+K26 -> 0.33333333
A27: P404 | B27: EDHINO | E27: =IF(D27>C27,D27-C27,C27-D27) -> 0 | H27: =IF(G27>F27,G27-F27,F27-G27) -> 0 | K27: =IF(J27>I27,J27-I27,I27-J27) -> 0 | L27: =E27+H27+K27 -> 0 | M27: REPOS
A28: P472 | B28: HERMANN | E28: =IF(D28>C28,D28-C28,C28-D28) -> 0 | F28: 0.58333333 | G28: 0.75 | H28: =IF(G28>F28,G28-F28,F28-G28) -> 0.16666667 | I28: 0.75 | J28: 0.91666667 | K28: =IF(J28>I28,J28-I28,I28-J28) -> 0.16666667 | L28: =E28+H28+K28 -> 0.33333333
A29: P324 | B29: JEAN CHRYS | E29: =IF(D29>C29,D29-C29,C29-D29) -> 0 | F29: 0.58333333 | G29: 0.75 | H29: =IF(G29>F29,G29-F29,F29-G29) -> 0.16666667 | I29: 0.75 | J29: 0.91666667 | K29: =IF(J29>I29,J29-I29,I29-J29) -> 0.16666667 | L29: =E29+H29+K29 -> 0.33333333
A30: P469 | B30: RAVAKA | C30: 0.25 | D30: 0.5 | E30: =IF(D30>C30,D30-C30,C30-D30) -> 0.25 | F30: 0.5 | G30: 0.58333333 | H30: =IF(G30>F30,G30-F30,F30-G30) -> 0.083333333 | K30: =IF(J30>I30,J30-I30,I30-J30) -> 0 | L30: =E30+H30+K30 -> 0.33333333
A31: P268 | B31: ROLAND | C31: 0.25 | D31: 0.5 | E31: =IF(D31>C31,D31-C31,C31-D31) -> 0.25 | F31: 0.5 | G31: 0.58333333 | H31: =IF(G31>F31,G31-F31,F31-G31) -> 0.083333333 | K31: =IF(J31>I31,J31-I31,I31-J31) -> 0 | L31: =E31+H31+K31 -> 0.33333333
A32: P419 | B32: ZIANI | E32: =IF(D32>C32,D32-C32,C32-D32) -> 0 | H32: =IF(G32>F32,G32-F32,F32-G32) -> 0 | K32: =IF(J32>I32,J32-I32,I32-J32) -> 0 | L32: =E32+H32+K32 -> 0 | M32: REPOS
A33: Stagiaire | B33: JIMMY | C33: 0.25 | D33: 0.5 | E33: =IF(D33>C33,D33-C33,C33-D33) -> 0.25 | F33: 0.5 | G33: 0.58333333 | H33: =IF(G33>F33,G33-F33,F33-G33) -> 0.083333333 | K33: =IF(J33>I33,J33-I33,I33-J33) -> 0 | L33: =E33+H33+K33 -> 0.33333333
A34: Stagiaire | B34: MANOELA | E34: =IF(D34>C34,D34-C34,C34-D34) -> 0 | F34: 0.58333333 | G34: 0.75 | H34: =IF(G34>F34,G34-F34,F34-G34) -> 0.16666667 | I34: 0.75 | J34: 0.91666667 | K34: =IF(J34>I34,J34-I34,I34-J34) -> 0.16666667 | L34: =E34+H34+K34 -> 0.33333333
E35: =SUM(E24:E34) -> 1 | H35: =SUM(H24:H34) -> 1 | K35: =SUM(K24:K34) -> 0.66666667 | L35: =SUM(L24:L34) -> 2.6666667
C38: CUISINE SNACK | G38: MERCREDI | H38: =+H21+1 -> 46246
C39: matin | F39: après-midi | I39: soir
B40: Personne | C40: entrée | D40: sortie | E40: durée | F40: entrée | G40: sortie | H40: durée | I40: entrée | J40: sortie | K40: durée | L40: durée total
A41: P477 | B41: ANYAH | E41: =IF(D41>C41,D41-C41,C41-D41) -> 0 | H41: =IF(G41>F41,G41-F41,F41-G41) -> 0 | K41: =IF(J41>I41,J41-I41,I41-J41) -> 0 | L41: =E41+H41+K41 -> 0 | M41: REPOS
A42: P522 | B42: AVOTRA | C42: 0.25 | D42: 0.5 | E42: =IF(D42>C42,D42-C42,C42-D42) -> 0.25 | F42: 0.5 | G42: 0.58333333 | H42: =IF(G42>F42,G42-F42,F42-G42) -> 0.083333333 | K42: =IF(J42>I42,J42-I42,I42-J42) -> 0 | L42: =E42+H42+K42 -> 0.33333333
A43: P543 | B43: AUGUSTIN | E43: =IF(D43>C43,D43-C43,C43-D43) -> 0 | F43: 0.58333333 | G43: 0.75 | H43: =IF(G43>F43,G43-F43,F43-G43) -> 0.16666667 | I43: 0.75 | J43: 0.91666667 | K43: =IF(J43>I43,J43-I43,I43-J43) -> 0.16666667 | L43: =E43+H43+K43 -> 0.33333333
A44: P404 | B44: EDHINO | E44: =IF(D44>C44,D44-C44,C44-D44) -> 0 | F44: 0.58333333 | G44: 0.75 | H44: =IF(G44>F44,G44-F44,F44-G44) -> 0.16666667 | I44: 0.75 | J44: 0.91666667 | K44: =IF(J44>I44,J44-I44,I44-J44) -> 0.16666667 | L44: =E44+H44+K44 -> 0.33333333
A45: P472 | B45: HERMANN | E45: =IF(D45>C45,D45-C45,C45-D45) -> 0 | H45: =IF(G45>F45,G45-F45,F45-G45) -> 0 | K45: =IF(J45>I45,J45-I45,I45-J45) -> 0 | L45: =E45+H45+K45 -> 0 | M45: REPOS
A46: P324 | B46: JEAN CHRYS | E46: =IF(D46>C46,D46-C46,C46-D46) -> 0 | F46: 0.58333333 | G46: 0.75 | H46: =IF(G46>F46,G46-F46,F46-G46) -> 0.16666667 | I46: 0.75 | J46: 0.91666667 | K46: =IF(J46>I46,J46-I46,I46-J46) -> 0.16666667 | L46: =E46+H46+K46 -> 0.33333333
A47: P469 | B47: RAVAKA | C47: 0.25 | D47: 0.5 | E47: =IF(D47>C47,D47-C47,C47-D47) -> 0.25 | F47: 0.5 | G47: 0.58333333 | H47: =IF(G47>F47,G47-F47,F47-G47) -> 0.083333333 | K47: =IF(J47>I47,J47-I47,I47-J47) -> 0 | L47: =E47+H47+K47 -> 0.33333333
...

Sheet SALLE SNACK
E2: EMPLOI DU TEMPS SALLE SNACK WEEK 37
C5: SALLE SNACK | G5: LUNDI | H5: 46244
C6: matin | F6: après-midi | I6: soir
B7: Personne | C7: entrée | D7: sortie | E7: durée | F7: entrée | G7: sortie | H7: durée | I7: entrée | J7: sortie | K7: durée | L7: durée total
A8: P513 | B8: FITIA | C8: 0.25 | D8: 0.41666667 | E8: =IF(D8>C8,D8-C8,C8-D8) -> 0.16666667 | F8: 0.58333333 | G8: 0.75 | H8: =IF(G8>F8,G8-F8,F8-G8) -> 0.16666667 | I8: 0.75 | J8: 0.91666667 | K8: =IF(J8>I8,J8-I8,I8-J8) -> 0.16666667 | L8: =E8+H8+K8 -> 0.5
A9: P511 | B9: TAHIRY | E9: =IF(D9>C9,D9-C9,C9-D9) -> 0 | F9: 0.58333333 | G9: 0.75 | H9: =IF(G9>F9,G9-F9,F9-G9) -> 0.16666667 | I9: 0.75 | J9: 0.91666667 | K9: =IF(J9>I9,J9-I9,I9-J9) -> 0.16666667 | L9: =E9+H9+K9 -> 0.33333333
A10: P313 | B10: TANTELY | C10: 0.25 | D10: 0.5 | E10: =IF(D10>C10,D10-C10,C10-D10) -> 0.25 | F10: 0.5 | G10: 0.58333333 | H10: =IF(G10>F10,G10-F10,F10-G10) -> 0.083333333 | K10: =IF(J10>I10,J10-I10,I10-J10) -> 0 | L10: =E10+H10+K10 -> 0.33333333
A11: P474 | B11: TINA | E11: =IF(D11>C11,D11-C11,C11-D11) -> 0 | F11: 0.58333333 | G11: 0.75 | H11: =IF(G11>F11,G11-F11,F11-G11) -> 0.16666667 | I11: 0.75 | J11: 0.91666667 | K11: =IF(J11>I11,J11-I11,I11-J11) -> 0.16666667 | L11: =E11+H11+K11 -> 0.33333333
A12: P540 | B12: CLARAH | E12: =IF(D12>C12,D12-C12,C12-D12) -> 0 | F12: 0.58333333 | G12: 0.75 | H12: =IF(G12>F12,G12-F12,F12-G12) -> 0.16666667 | I12: 0.75 | J12: 0.91666667 | K12: =IF(J12>I12,J12-I12,I12-J12) -> 0.16666667 | L12: =E12+H12+K12 -> 0.33333333
A13: P551 | B13: FIANTSA | C13: 0.25 | D13: 0.5 | E13: =IF(D13>C13,D13-C13,C13-D13) -> 0.25 | F13: 0.5 | G13: 0.58333333 | H13: =IF(G13>F13,G13-F13,F13-G13) -> 0.083333333 | K13: =IF(J13>I13,J13-I13,I13-J13) -> 0 | L13: =E13+H13+K13 -> 0.33333333
A14: P332 | B14: ALIDAH | C14: 0.25 | D14: 0.5 | E14: =IF(D14>C14,D14-C14,C14-D14) -> 0.25 | F14: 0.5 | G14: 0.58333333 | H14: =IF(G14>F14,G14-F14,F14-G14) -> 0.083333333 | K14: =IF(J14>I14,J14-I14,I14-J14) -> 0 | L14: =E14+H14+K14 -> 0.33333333
A15: Stagiaire | B15: CHRISTOPHE | E15: =IF(D15>C15,D15-C15,C15-D15) -> 0 | H15: =IF(G15>F15,G15-F15,F15-G15) -> 0 | K15: =IF(J15>I15,J15-I15,I15-J15) -> 0 | L15: =E15+H15+K15 -> 0 | M15: REPOS
A16: Stagiaire | B16: MITIA | E16: =IF(D16>C16,D16-C16,C16-D16) -> 0 | H16: =IF(G16>F16,G16-F16,F16-G16) -> 0 | K16: =IF(J16>I16,J16-I16,I16-J16) -> 0 | L16: =E16+H16+K16 -> 0 | M16: REPOS
E17: =SUM(E8:E16) -> 0.91666667 | H17: =SUM(H8:H16) -> 0.91666667 | K17: =SUM(K8:K16) -> 0.66666667 | L17: =SUM(L8:L16) -> 2.5
C19: SALLE SNACK | G19: MARDI | H19: =+H5+1 -> 46245
C20: matin | F20: après-midi | I20: soir
B21: Personne | C21: entrée | D21: sortie | E21: durée | F21: entrée | G21: sortie | H21: durée | I21: entrée | J21: sortie | K21: durée | L21: durée total
A22: P513 | B22: FITIA | E22: =IF(D22>C22,D22-C22,C22-D22) -> 0 | H22: =IF(G22>F22,G22-F22,F22-G22) -> 0 | K22: =IF(J22>I22,J22-I22,I22-J22) -> 0 | L22: =E22+H22+K22 -> 0 | M22: REPOS
A23: P511 | B23: TAHIRY | E23: =IF(D23>C23,D23-C23,C23-D23) -> 0 | F23: 0.58333333 | G23: 0.75 | H23: =IF(G23>F23,G23-F23,F23-G23) -> 0.16666667 | I23: 0.75 | J23: 0.91666667 | K23: =IF(J23>I23,J23-I23,I23-J23) -> 0.16666667 | L23: =E23+H23+K23 -> 0.33333333
A24: P313 | B24: TANTELY | C24: 0.25 | D24: 0.5 | E24: =IF(D24>C24,D24-C24,C24-D24) -> 0.25 | F24: 0.5 | G24: 0.58333333 | H24: =IF(G24>F24,G24-F24,F24-G24) -> 0.083333333 | K24: =IF(J24>I24,J24-I24,I24-J24) -> 0 | L24: =E24+H24+K24 -> 0.33333333 | M24: CM
A25: P474 | B25: TINA | E25: =IF(D25>C25,D25-C25,C25-D25) -> 0 | F25: 0.58333333 | G25: 0.75 | H25: =IF(G25>F25,G25-F25,F25-G25) -> 0.16666667 | I25: 0.75 | J25: 0.91666667 | K25: =IF(J25>I25,J25-I25,I25-J25) -> 0.16666667 | L25: =E25+H25+K25 -> 0.33333333 | M25: CM
A26: P540 | B26: CLARAH | E26: =IF(D26>C26,D26-C26,C26-D26) -> 0 | F26: 0.58333333 | G26: 0.75 | H26: =IF(G26>F26,G26-F26,F26-G26) -> 0.16666667 | I26: 0.75 | J26: 0.91666667 | K26: =IF(J26>I26,J26-I26,I26-J26) -> 0.16666667 | L26: =E26+H26+K26 -> 0.33333333
A27: P551 | B27: FIANTSA | C27: 0.25 | D27: 0.5 | E27: =IF(D27>C27,D27-C27,C27-D27) -> 0.25 | F27: 0.5 | G27: 0.58333333 | H27: =IF(G27>F27,G27-F27,F27-G27) -> 0.083333333 | K27: =IF(J27>I27,J27-I27,I27-J27) -> 0 | L27: =E27+H27+K27 -> 0.33333333 | M27: CM
A28: P332 | B28: ALIDAH | C28: 0.25 | D28: 0.5 | E28: =IF(D28>C28,D28-C28,C28-D28) -> 0.25 | F28: 0.5 | G28: 0.58333333 | H28: =IF(G28>F28,G28-F28,F28-G28) -> 0.083333333 | K28: =IF(J28>I28,J28-I28,I28-J28) -> 0 | L28: =E28+H28+K28 -> 0.33333333 | M28: CM
A29: Stagiaire | B29: CHRISTOPHE | C29: 0.25 | D29: 0.5 | E29: =IF(D29>C29,D29-C29,C29-D29) -> 0.25 | F29: 0.5 | G29: 0.58333333 | H29: =IF(G29>F29,G29-F29,F29-G29) -> 0.083333333 | K29: =IF(J29>I29,J29-I29,I29-J29) -> 0 | L29: =E29+H29+K29 -> 0.33333333 | M29: CM
A30: Stagiaire | B30: MITIA | E30: =IF(D30>C30,D30-C30,C30-D30) -> 0 | F30: 0.58333333 | G30: 0.75 | H30: =IF(G30>F30,G30-F30,F30-G30) -> 0.16666667 | I30: 0.75 | J30: 0.91666667 | K30: =IF(J30>I30,J30-I30,I30-J30) -> 0.16666667 | L30: =E30+H30+K30 -> 0.33333333 | M30: CM
E31: =SUM(E22:E30) -> 1 | H31: =SUM(H22:H30) -> 1 | K31: =SUM(K22:K30) -> 0.66666667 | L31: =SUM(L22:L30) -> 2.6666667
C33: SALLE SNACK | G33: MERCREDI | H33: =+H19+1 -> 46246
C34: matin | F34: après-midi | I34: soir
B35: Personne | C35: entrée | D35: sortie | E35: durée | F35: entrée | G35: sortie | H35: durée | I35: entrée | J35: sortie | K35: durée | L35: durée total
A36: P513 | B36: FITIA | E36: =IF(D36>C36,D36-C36,C36-D36) -> 0 | F36: 0.58333333 | G36: 0.75 | H36: =IF(G36>F36,G36-F36,F36-G36) -> 0.16666667 | I36: 0.75 | J36: 0.91666667 | K36: =IF(J36>I36,J36-I36,I36-J36) -> 0.16666667 | L36: =E36+H36+K36 -> 0.33333333
A37: P511 | B37: TAHIRY | E37: =IF(D37>C37,D37-C37,C37-D37) -> 0 | H37: =IF(G37>F37,G37-F37,F37-G37) -> 0 | K37: =IF(J37>I37,J37-I37,I37-J37) -> 0 | L37: =E37+H37+K37 -> 0 | M37: REPOS
A38: P313 | B38: TANTELY | C38: 0.25 | D38: 0.5 | E38: =IF(D38>C38,D38-C38,C38-D38) -> 0.25 | F38: 0.5 | G38: 0.58333333 | H38: =IF(G38>F38,G38-F38,F38-G38) -> 0.083333333 | K38: =IF(J38>I38,J38-I38,I38-J38) -> 0 | L38: =E38+H38+K38 -> 0.33333333
A39: P474 | B39: TINA | E39: =IF(D39>C39,D39-C39,C39-D39) -> 0 | F39: 0.58333333 | G39: 0.75 | H39: =IF(G39>F39,G39-F39,F39-G39) -> 0.16666667 | I39: 0.75 | J39: 0.91666667 | K39: =IF(J39>I39,J39-I39,I39-J39) -> 0.16666667 | L39: =E39+H39+K39 -> 0.33333333
A40: P540 | B40: CLARAH | E40: =IF(D40>C40,D40-C40,C40-D40) -> 0 | F40: 0.58333333 | G40: 0.75 | H40: =IF(G40>F40,G40-F40,F40-G40) -> 0.16666667 | I40: 0.75 | J40: 0.91666667 | K40: =IF(J40>I40,J40-I40,I40-J40) -> 0.16666667 | L40: =E40+H40+K40 -> 0.33333333
A41: P551 | B41: FIANTSA | C41: 0.25 | D41: 0.5 | E41: =IF(D41>C41,D41-C41,C41-D41) -> 0.25 | F41: 0.5 | G41: 0.58333333 | H41: =IF(G41>F41,G41-F41,F41-G41) -> 0.083333333 | K41: =IF(J41>I41,J41-I41,I41-J41) -> 0 | L41: =E41+H41+K41 -> 0.33333333
A42: P332 | B42: ALIDAH | C42: 0.25 | D42: 0.5 | E42: =IF(D42>C42,D42-C42,C42-D42) -> 0.25 | F42: 0.5 | G42: 0.58333333 | H42: =IF(G42>F42,G42-F42,F42-G42) -> 0.083333333 | K42: =IF(J42>I42,J42-I42,I42-J42) -> 0 | L42: =E42+H42+K42 -> 0.33333333
A43: Stagiaire | B43: CHRISTOPHE | C43: 0.25 | D43: 0.5 | E43: =IF(D43>C43,D43-C43,C43-D43) -> 0.25 | F43: 0.5 | G43: 0.58333333 | H43: =IF(G43>F43,G43-F43,F43-G43) -> 0.083333333 | K43: =IF(J43>I43,J43-I43,I43-J43) -> 0 | L43: =E43+H43+K43 -> 0.33333333
A44: Stagiaire | B44: MITIA | E44: =IF(D44>C44,D44-C44,C44-D44) -> 0 | F44: 0.58333333 | G44: 0.75 | H44: =IF(G44>F44,G44-F44,F44-G44) -> 0.16666667 | I44: 0.75 | J44: 0.91666667 | K44: =IF(J44>I44,J44-I44,I44-J44) -> 0.16666667 | L44: =E44+H44+K44 -> 0.33333333
E45: =SUM(E36:E44) -> 1 | H45: =SUM(H36:H44) -> 1 | K45: =SUM(K36:K44) -> 0.66666667 | L45: =SUM(L36:L44) -> 2.6666667
...

Sheet PATISS-PIZZA
E2: EMPLOI DU TEMPS PATISSERIE-PIZZA WEEK 36
C5: PATISSERIE & PIZZA | G5: =+MAINTENANCE!G5 -> LUNDI | H5: =+'CUISINE SNACK'!H5 -> 46244
C6: matin | F6: après-midi | I6: soir
B7: Personne | C7: entrée | D7: sortie | E7: durée | F7: entrée | G7: sortie | H7: durée | I7: entrée | J7: sortie | K7: durée | L7: durée total
A8: P497 | B8: FREDDY | C8: 0.1875 | D8: 0.52083333 | E8: =IF(D8>C8,D8-C8,C8-D8) -> 0.33333333 | H8: =IF(G8>F8,G8-F8,F8-G8) -> 0 | K8: =IF(J8>I8,J8-I8,I8-J8) -> 0 | L8: =E8+H8+K8 -> 0.33333333
A9: P297 | B9: RIRI | C9: 0.1875 | D9: 0.52083333 | E9: =IF(D9>C9,D9-C9,C9-D9) -> 0.33333333 | H9: =IF(G9>F9,G9-F9,F9-G9) -> 0 | K9: =IF(J9>I9,J9-I9,I9-J9) -> 0 | L9: =E9+H9+K9 -> 0.33333333
A10: P353 | B10: FLORIDA | C10: 0.41666667 | D10: 0.58333333 | E10: =IF(D10>C10,D10-C10,C10-D10) -> 0.16666667 | F10: 0.58333333 | G10: 0.75 | H10: =IF(G10>F10,G10-F10,F10-G10) -> 0.16666667 | I10: 0.75 | J10: 0.91666667 | K10: =IF(J10>I10,J10-I10,I10-J10) -> 0.16666667 | L10: =E10+H10+K10 -> 0.5
B11: CHRISTIAN | C11: 0.1875 | D11: 0.52083333
B12: ANDRY | E12: =IF(D12>C12,D12-C12,C12-D12) -> 0 | H12: =IF(G12>F12,G12-F12,F12-G12) -> 0 | M12: REPOS
A13: P399 | B13: BOSCO | E13: =IF(D13>C13,D13-C13,C13-D13) -> 0 | H13: =IF(G13>F13,G13-F13,F13-G13) -> 0 | M13: REPOS
A14: Stagiaire | B14: STAN | E14: =IF(D14>C14,D14-C14,C14-D14) -> 0 | H14: =IF(G14>F14,G14-F14,F14-G14) -> 0 | M14: REPOS
A15: Stagiaire | B15: MATHILDA | C15: 0.25 | D15: 0.5 | E15: =IF(D15>C15,D15-C15,C15-D15) -> 0.25 | F15: 0.5 | G15: 0.58333333 | H15: =IF(G15>F15,G15-F15,F15-G15) -> 0.083333333 | K15: =IF(J15>I15,J15-I15,I15-J15) -> 0 | L15: =E15+H15+K15 -> 0.33333333
E16: =SUM(E8:E15) -> 1.0833333 | H16: =SUM(H8:H15) -> 0.25 | K16: =SUM(K8:K15) -> 0.16666667 | L16: =SUM(L8:L15) -> 1.5
C18: =+C5 -> PATISSERIE & PIZZA | G18: MARDI | H18: =+H5+1 -> 46245
C19: matin | F19: après-midi | I19: soir
B20: Personne | C20: entrée | D20: sortie | E20: durée | F20: entrée | G20: sortie | H20: durée | I20: entrée | J20: sortie | K20: durée | L20: durée total
A21: P497 | B21: FREDDY | E21: =IF(D21>C21,D21-C21,C21-D21) -> 0 | H21: =IF(G21>F21,G21-F21,F21-G21) -> 0 | K21: =IF(J21>I21,J21-I21,I21-J21) -> 0 | L21: =E21+H21+K21 -> 0 | M21: REPOS
A22: P297 | B22: RIRI | C22: 0.1875 | D22: 0.52083333 | E22: =IF(D22>C22,D22-C22,C22-D22) -> 0.33333333 | H22: =IF(G22>F22,G22-F22,F22-G22) -> 0 | K22: =IF(J22>I22,J22-I22,I22-J22) -> 0 | L22: =E22+H22+K22 -> 0.33333333
B23: ANDRY | C23: 0.1875 | D23: 0.52083333 | E23: =IF(D23>C23,D23-C23,C23-D23) -> 0.33333333 | H23: =IF(G23>F23,G23-F23,F23-G23) -> 0 | K23: =IF(J23>I23,J23-I23,I23-J23) -> 0 | L23: =E23+H23+K23 -> 0.33333333
B24: CHRISTIAN | C24: 0.1875 | D24: 0.52083333 | E24: =IF(D24>C24,D24-C24,C24-D24) -> 0.33333333 | H24: =IF(G24>F24,G24-F24,F24-G24) -> 0 | K24: =IF(J24>I24,J24-I24,I24-J24) -> 0 | L24: =E24+H24+K24 -> 0.33333333
A25: P353 | B25: FLORIDA | E25: =IF(D25>C25,D25-C25,C25-D25) -> 0 | H25: =IF(G25>F25,G25-F25,F25-G25) -> 0 | K25: =IF(J25>I25,J25-I25,I25-J25) -> 0 | L25: =E25+H25+K25 -> 0 | M25: REPOS
A26: P399 | B26: BOSCO | C26: 0.41666667 | D26: 0.58333333 | E26: =IF(D26>C26,D26-C26,C26-D26) -> 0.16666667 | F26: 0.58333333 | G26: 0.75 | H26: =IF(G26>F26,G26-F26,F26-G26) -> 0.16666667 | I26: 0.75 | J26: 0.91666667 | K26: =IF(J26>I26,J26-I26,I26-J26) -> 0.16666667 | L26: =E26+H26+K26 -> 0.5
A27: Stagiaire | B27: MATHILDA | C27: 0.25 | D27: 0.5 | E27: =IF(D27>C27,D27-C27,C27-D27) -> 0.25 | F27: 0.5 | G27: 0.58333333 | H27: =IF(G27>F27,G27-F27,F27-G27) -> 0.083333333 | K27: =IF(J27>I27,J27-I27,I27-J27) -> 0 | L27: =E27+H27+K27 -> 0.33333333
A28: Stagiaire | B28: STAN | C28: 0.25 | D28: 0.5 | E28: =IF(D28>C28,D28-C28,C28-D28) -> 0.25 | F28: 0.5 | G28: 0.58333333 | H28: =IF(G28>F28,G28-F28,F28-G28) -> 0.083333333 | K28: =IF(J28>I28,J28-I28,I28-J28) -> 0 | L28: =E28+H28+K28 -> 0.33333333
E29: =SUM(E21:E28) -> 1.6666667 | H29: =SUM(H21:H28) -> 0.33333333 | K29: =SUM(K21:K28) -> 0.16666667 | L29: =SUM(L21:L28) -> 2.1666667
C31: =+C18 -> PATISSERIE & PIZZA | G31: MERCREDI | H31: =+H18+1 -> 46246
C32: matin | F32: après-midi | I32: soir
B33: Personne | C33: entrée | D33: sortie | E33: durée | F33: entrée | G33: sortie | H33: durée | I33: entrée | J33: sortie | K33: durée | L33: durée total
A34: P497 | B34: FREDDY | C34: 0.1875 | D34: 0.52083333 | E34: =IF(D34>C34,D34-C34,C34-D34) -> 0.33333333 | H34: =IF(G34>F34,G34-F34,F34-G34) -> 0 | K34: =IF(J34>I34,J34-I34,I34-J34) -> 0 | L34: =E34+H34+K34 -> 0.33333333
A35: P297 | B35: RIRI | C35: 0.1875 | D35: 0.52083333 | E35: =IF(D35>C35,D35-C35,C35-D35) -> 0.33333333 | H35: =IF(G35>F35,G35-F35,F35-G35) -> 0 | K35: =IF(J35>I35,J35-I35,I35-J35) -> 0 | L35: =E35+H35+K35 -> 0.33333333
B36: CHRISTIAN | E36: =IF(D36>C36,D36-C36,C36-D36) -> 0 | H36: =IF(G36>F36,G36-F36,F36-G36) -> 0 | K36: =IF(J36>I36,J36-I36,I36-J36) -> 0 | L36: =E36+H36+K36 -> 0 | M36: REPOS
B37: ANDRY | C37: 0.1875 | D37: 0.52083333 | E37: =IF(D37>C37,D37-C37,C37-D37) -> 0.33333333 | H37: =IF(G37>F37,G37-F37,F37-G37) -> 0 | K37: =IF(J37>I37,J37-I37,I37-J37) -> 0 | L37: =E37+H37+K37 -> 0.33333333
A38: P353 | B38: FLORIDA | E38: =IF(D38>C38,D38-C38,C38-D38) -> 0 | H38: =IF(G38>F38,G38-F38,F38-G38) -> 0 | K38: =IF(J38>I38,J38-I38,I38-J38) -> 0 | L38: =E38+H38+K38 -> 0 | M38: REPOS
A39: P399 | B39: BOSCO | C39: 0.41666667 | D39: 0.58333333 | E39: =IF(D39>C39,D39-C39,C39-D39) -> 0.16666667 | F39: 0.58333333 | G39: 0.75 | H39: =IF(G39>F39,G39-F39,F39-G39) -> 0.16666667 | I39: 0.75 | J39: 0.91666667 | K39: =IF(J39>I39,J39-I39,I39-J39) -> 0.16666667 | L39: =E39+H39+K39 -> 0.5
A40: Stagiaire | B40: MATHILDA | E40: =IF(D40>C40,D40-C40,C40-D40) -> 0 | H40: =IF(G40>F40,G40-F40,F40-G40) -> 0 | K40: =IF(J40>I40,J40-I40,I40-J40) -> 0 | L40: =E40+H40+K40 -> 0 | M40: REPOS
A41: Stagiaire | B41: STAN | C41: 0.25 | D41: 0.5 | E41: =IF(D41>C41,D41-C41,C41-D41) -> 0.25 | F41: 0.5 | G41: 0.58333333 | H41: =IF(G41>F41,G41-F41,F41-G41) -> 0.083333333 | K41: =IF(J41>I41,J41-I41,I41-J41) -> 0 | L41: =E41+H41+K41 -> 0.33333333
E42: =SUM(E34:E41) -> 1.4166667 | H42: =SUM(H34:H41) -> 0.25 | K42: =SUM(K34:K41) -> 0.16666667 | L42: =SUM(L34:L41) -> 1.8333333
C44: =+C31 -> PATISSERIE & PIZZA | G44: JEUDI | H44: =+H31+1 -> 46247
C45: matin | F45: après-midi | I45: soir
B46: Personne | C46: entrée | D46: sortie | E46: durée | F46: entrée | G46: sortie | H46: durée | I46: entrée | J46: sortie | K46: durée | L46: durée total
...

Sheet CUISINE CANTINE
E2: EMPLOI DU TEMPS CUISINE CANTINE WEEK 36
C5: CUISINE CANTINE | G5: LUNDI | H5: =+'PATISS-PIZZA'!H5 -> 46244
C6: matin | F6: après-midi | I6: soir
B7: Personne | C7: entrée | D7: sortie | E7: durée | F7: entrée | G7: sortie | H7: durée | I7: entrée | J7: sortie | K7: durée | L7: durée total
A8: - | B8: ZOLY | C8: 0.25 | D8: 0.58333333 | E8: =IF(D8>C8,D8-C8,C8-D8) -> 0.33333333 | H8: =IF(G8>F8,G8-F8,F8-G8) -> 0 | I8: 0.75 | J8: 0.91666667 | K8: =IF(J8>I8,J8-I8,I8-J8) -> 0.16666667 | L8: =E8+H8+K8 -> 0.5
A9: P524 | B9: CEDRIC | E9: =IF(D9>C9,D9-C9,C9-D9) -> 0 | H9: =IF(G9>F9,G9-F9,F9-G9) -> 0 | K9: =IF(J9>I9,J9-I9,I9-J9) -> 0 | L9: =E9+H9+K9 -> 0 | M9: REPOS
E10: =SUM(E8:E9) -> 0.33333333 | H10: =SUM(H8:H9) -> 0 | K10: =SUM(K8:K9) -> 0.16666667 | L10: =SUM(L8:L9) -> 0.5
C12: =+C5 -> CUISINE CANTINE | G12: MARDI | H12: =+H5+1 -> 46245
C13: matin | F13: après-midi | I13: soir
B14: Personne | C14: entrée | D14: sortie | E14: durée | F14: entrée | G14: sortie | H14: durée | I14: entrée | J14: sortie | K14: durée | L14: durée total
A15: - | B15: ZOLY | E15: =IF(D15>C15,D15-C15,C15-D15) -> 0 | H15: =IF(G15>F15,G15-F15,F15-G15) -> 0 | K15: =IF(J15>I15,J15-I15,I15-J15) -> 0 | L15: =E15+H15+K15 -> 0 | M15: REPOS
A16: P524 | B16: CEDRIC | C16: 0.25 | D16: 0.58333333 | E16: =IF(D16>C16,D16-C16,C16-D16) -> 0.33333333 | H16: =IF(G16>F16,G16-F16,F16-G16) -> 0 | I16: 0.75 | J16: 0.91666667 | K16: =IF(J16>I16,J16-I16,I16-J16) -> 0.16666667 | L16: =E16+H16+K16 -> 0.5
E17: =SUM(E15:E16) -> 0.33333333 | H17: =SUM(H15:H16) -> 0 | K17: =SUM(K15:K16) -> 0.16666667 | L17: =SUM(L15:L16) -> 0.5
C18: =+C12 -> CUISINE CANTINE | G18: MERCREDI | H18: =+H12+1 -> 46246
C19: matin | F19: après-midi | I19: soir
B20: Personne | C20: entrée | D20: sortie | E20: durée | F20: entrée | G20: sortie | H20: durée | I20: entrée | J20: sortie | K20: durée | L20: durée total
A21: - | B21: ZOLY | C21: 0.33333333 | D21: 0.58333333 | E21: =IF(D21>C21,D21-C21,C21-D21) -> 0.25 | H21: =IF(G21>F21,G21-F21,F21-G21) -> 0 | I21: 0.75 | J21: 0.91666667 | K21: =IF(J21>I21,J21-I21,I21-J21) -> 0.16666667 | L21: =E21+H21+K21 -> 0.41666667
A22: P524 | B22: CEDRIC | C22: 0.25 | D22: 0.5 | E22: =IF(D22>C22,D22-C22,C22-D22) -> 0.25 | F22: 0.5 | G22: 0.58333333 | H22: =IF(G22>F22,G22-F22,F22-G22) -> 0.083333333 | K22: =IF(J22>I22,J22-I22,I22-J22) -> 0 | L22: =E22+H22+K22 -> 0.33333333
E23: =SUM(E21:E22) -> 0.5 | H23: =SUM(H21:H22) -> 0.083333333 | K23: =SUM(K21:K22) -> 0.16666667 | L23: =SUM(L21:L22) -> 0.75
C24: =+C18 -> CUISINE CANTINE | G24: JEUDI | H24: =+H18+1 -> 46247
C25: matin | F25: après-midi | I25: soir
B26: Personne | C26: entrée | D26: sortie | E26: durée | F26: entrée | G26: sortie | H26: durée | I26: entrée | J26: sortie | K26: durée | L26: durée total
A27: - | B27: ZOLY | C27: 0.33333333 | D27: 0.58333333 | E27: =IF(D27>C27,D27-C27,C27-D27) -> 0.25 | H27: =IF(G27>F27,G27-F27,F27-G27) -> 0 | I27: 0.75 | J27: 0.91666667 | K27: =IF(J27>I27,J27-I27,I27-J27) -> 0.16666667 | L27: =E27+H27+K27 -> 0.41666667
A28: P524 | B28: CEDRIC | C28: 0.25 | D28: 0.5 | E28: =IF(D28>C28,D28-C28,C28-D28) -> 0.25 | F28: 0.5 | G28: 0.58333333 | H28: =IF(G28>F28,G28-F28,F28-G28) -> 0.083333333 | K28: =IF(J28>I28,J28-I28,I28-J28) -> 0 | L28: =E28+H28+K28 -> 0.33333333
E29: =SUM(E27:E28) -> 0.5 | H29: =SUM(H27:H28) -> 0.083333333 | K29: =SUM(K27:K28) -> 0.16666667 | L29: =SUM(L27:L28) -> 0.75
C30: =+C24 -> CUISINE CANTINE | G30: VENDREDI | H30: =+H24+1 -> 46248
C31: matin | F31: après-midi | I31: soir
B32: Personne | C32: entrée | D32: sortie | E32: durée | F32: entrée | G32: sortie | H32: durée | I32: entrée | J32: sortie | K32: durée | L32: durée total
A33: - | B33: ZOLY | C33: 0.33333333 | D33: 0.58333333 | E33: =IF(D33>C33,D33-C33,C33-D33) -> 0.25 | H33: =IF(G33>F33,G33-F33,F33-G33) -> 0 | I33: 0.75 | J33: 0.91666667 | K33: =IF(J33>I33,J33-I33,I33-J33) -> 0.16666667 | L33: =E33+H33+K33 -> 0.41666667
A34: P524 | B34: CEDRIC | C34: 0.25 | D34: 0.5 | E34: =IF(D34>C34,D34-C34,C34-D34) -> 0.25 | F34: 0.5 | G34: 0.58333333 | H34: =IF(G34>F34,G34-F34,F34-G34) -> 0.083333333 | K34: =IF(J34>I34,J34-I34,I34-J34) -> 0 | L34: =E34+H34+K34 -> 0.33333333
E35: =SUM(E33:E34) -> 0.5 | H35: =SUM(H33:H34) -> 0.083333333 | K35: =SUM(K33:K34) -> 0.16666667 | L35: =SUM(L33:L34) -> 0.75
C36: =+C30 -> CUISINE CANTINE | G36: SAMEDI | H36: =+H30+1 -> 46249
C37: matin | F37: après-midi | I37: soir
B38: Personne | C38: entrée | D38: sortie | E38: durée | F38: entrée | G38: sortie | H38: durée | I38: entrée | J38: sortie | K38: durée | L38: durée total
A39: - | B39: ZOLY | C39: 0.33333333 | D39: 0.58333333 | E39: =IF(D39>C39,D39-C39,C39-D39) -> 0.25 | H39: =IF(G39>F39,G39-F39,F39-G39) -> 0 | I39: 0.75 | J39: 0.91666667 | K39: =IF(J39>I39,J39-I39,I39-J39) -> 0.16666667 | L39: =E39+H39+K39 -> 0.41666667
A40: P524 | B40: CEDRIC | C40: 0.25 | D40: 0.5 | E40: =IF(D40>C40,D40-C40,C40-D40) -> 0.25 | F40: 0.5 | G40: 0.58333333 | H40: =IF(G40>F40,G40-F40,F40-G40) -> 0.083333333 | K40: =IF(J40>I40,J40-I40,I40-J40) -> 0 | L40: =E40+H40+K40 -> 0.33333333
E41: =SUM(E39:E40) -> 0.5 | H41: =SUM(H39:H40) -> 0.083333333 | K41: =SUM(K39:K40) -> 0.16666667 | L41: =SUM(L39:L40) -> 0.75
C42: =+C36 -> CUISINE CANTINE | G42: DIMANCHE | H42: =+H36+1 -> 46250
C43: matin | F43: après-midi | I43: soir
B44: Personne | C44: entrée | D44: sortie | E44: durée | F44: entrée | G44: sortie | H44: durée | I44: entrée | J44: sortie | K44: durée | L44: durée total
...

Sheet CUISINE DETENTE
E2: EMPLOI DU TEMPS CUISINE DETENTE WEEK 36
C5: CUISINE DETENTE | G5: LUNDI | H5: =+'CUISINE CANTINE'!H5 -> 46244
C6: matin | F6: après-midi | I6: soir
B7: Personne | C7: entrée | D7: sortie | E7: durée | F7: entrée | G7: sortie | H7: durée | I7: entrée | J7: sortie | K7: durée | L7: durée total
A8: P515 | B8: JOHNNY | C8: 0.41666667 | D8: 0.58333333 | E8: =IF(D8>C8,D8-C8,C8-D8) -> 0.16666667 | H8: =IF(G8>F8,G8-F8,F8-G8) -> 0 | I8: 0.75 | J8: 0.91666667 | K8: =IF(J8>I8,J8-I8,I8-J8) -> 0.16666667 | L8: =E8+H8+K8 -> 0.33333333
A9: P524 | B9: CHRISTOPHE | E9: =IF(D9>C9,D9-C9,C9-D9) -> 0 | H9: =IF(G9>F9,G9-F9,F9-G9) -> 0 | K9: =IF(J9>I9,J9-I9,I9-J9) -> 0 | L9: =E9+H9+K9 -> 0 | M9: REPOS
B10: DAUDET | C10: 0.41666667 | D10: 0.58333333 | E10: =IF(D10>C10,D10-C10,C10-D10) -> 0.16666667 | H10: =IF(G10>F10,G10-F10,F10-G10) -> 0 | I10: 0.75 | J10: 0.91666667 | K10: =IF(J10>I10,J10-I10,I10-J10) -> 0.16666667 | L10: =E10+H10+K10 -> 0.33333333
E11: =SUM(E8:E10) -> 0.33333333 | H11: =SUM(H8:H10) -> 0 | K11: =SUM(K8:K10) -> 0.33333333 | L11: =SUM(L8:L10) -> 0.66666667
C13: =+C5 -> CUISINE DETENTE | G13: MARDI | H13: =+H5+1 -> 46245
C14: matin | F14: après-midi | I14: soir
B15: Personne | C15: entrée | D15: sortie | E15: durée | F15: entrée | G15: sortie | H15: durée | I15: entrée | J15: sortie | K15: durée | L15: durée total
A16: P515 | B16: JOHNNY | C16: 0.41666667 | D16: 0.58333333 | E16: =IF(D16>C16,D16-C16,C16-D16) -> 0.16666667 | H16: =IF(G16>F16,G16-F16,F16-G16) -> 0 | I16: 0.75 | J16: 0.91666667 | K16: =IF(J16>I16,J16-I16,I16-J16) -> 0.16666667 | L16: =E16+H16+K16 -> 0.33333333
A17: P524 | B17: CHRISTOPHE | E17: =IF(D17>C17,D17-C17,C17-D17) -> 0 | F17: 0.58333333 | G17: 0.75 | H17: =IF(G17>F17,G17-F17,F17-G17) -> 0.16666667 | I17: 0.75 | J17: 0.91666667 | K17: =IF(J17>I17,J17-I17,I17-J17) -> 0.16666667 | L17: =E17+H17+K17 -> 0.33333333
B18: DAUDET | E18: =IF(D18>C18,D18-C18,C18-D18) -> 0 | H18: =IF(G18>F18,G18-F18,F18-G18) -> 0 | K18: =IF(J18>I18,J18-I18,I18-J18) -> 0 | L18: =E18+H18+K18 -> 0 | M18: REPOS
E19: =SUM(E16:E18) -> 0.16666667 | H19: =SUM(H16:H18) -> 0.16666667 | K19: =SUM(K16:K18) -> 0.33333333 | L19: =SUM(L16:L18) -> 0.66666667
C20: =+C13 -> CUISINE DETENTE | G20: MERCREDI | H20: =+H13+1 -> 46246
C21: matin | F21: après-midi | I21: soir
B22: Personne | C22: entrée | D22: sortie | E22: durée | F22: entrée | G22: sortie | H22: durée | I22: entrée | J22: sortie | K22: durée | L22: durée total
A23: P515 | B23: JOHNNY | E23: =IF(D23>C23,D23-C23,C23-D23) -> 0 | H23: =IF(G23>F23,G23-F23,F23-G23) -> 0 | K23: =IF(J23>I23,J23-I23,I23-J23) -> 0 | L23: =E23+H23+K23 -> 0 | M23: REPOS
A24: P524 | B24: CHRISTOPHE | E24: =IF(D24>C24,D24-C24,C24-D24) -> 0 | H24: =IF(G24>F24,G24-F24,F24-G24) -> 0 | I24: 0.75 | J24: 0.91666667 | K24: =IF(J24>I24,J24-I24,I24-J24) -> 0.16666667 | L24: =E24+H24+K24 -> 0.16666667
B25: DAUDET | C25: 0.41666667 | D25: 0.58333333 | E25: =IF(D25>C25,D25-C25,C25-D25) -> 0.16666667 | H25: =IF(G25>F25,G25-F25,F25-G25) -> 0 | I25: 0.75 | J25: 0.91666667 | K25: =IF(J25>I25,J25-I25,I25-J25) -> 0.16666667 | L25: =E25+H25+K25 -> 0.33333333
E26: =SUM(E23:E24) -> 0 | H26: =SUM(H23:H24) -> 0 | K26: =SUM(K23:K24) -> 0.16666667 | L26: =SUM(L23:L24) -> 0.16666667
C27: =+C20 -> CUISINE DETENTE | G27: JEUDI | H27: =+H20+1 -> 46247
C28: matin | F28: après-midi | I28: soir
B29: Personne | C29: entrée | D29: sortie | E29: durée | F29: entrée | G29: sortie | H29: durée | I29: entrée | J29: sortie | K29: durée | L29: durée total
A30: P515 | B30: JOHNNY | C30: 0.41666667 | D30: 0.58333333 | E30: =IF(D30>C30,D30-C30,C30-D30) -> 0.16666667 | H30: =IF(G30>F30,G30-F30,F30-G30) -> 0 | I30: 0.75 | J30: 0.91666667 | K30: =IF(J30>I30,J30-I30,I30-J30) -> 0.16666667 | L30: =E30+H30+K30 -> 0.33333333
A31: P524 | B31: CHRISTOPHE | C31: 0.41666667 | D31: 0.58333333 | E31: =IF(D31>C31,D31-C31,C31-D31) -> 0.16666667 | H31: =IF(G31>F31,G31-F31,F31-G31) -> 0 | I31: 0.75 | J31: 0.91666667 | K31: =IF(J31>I31,J31-I31,I31-J31) -> 0.16666667 | L31: =E31+H31+K31 -> 0.33333333
B32: DAUDET | E32: =IF(D32>C32,D32-C32,C32-D32) -> 0 | F32: 0.58333333 | G32: 0.75 | H32: =IF(G32>F32,G32-F32,F32-G32) -> 0.16666667 | I32: 0.75 | J32: 0.91666667 | K32: =IF(J32>I32,J32-I32,I32-J32) -> 0.16666667 | L32: =E32+H32+K32 -> 0.33333333
E33: =SUM(E30:E31) -> 0.33333333 | H33: =SUM(H30:H31) -> 0 | K33: =SUM(K30:K32) -> 0.5 | L33: =SUM(L30:L32) -> 1
C34: =+C27 -> CUISINE DETENTE | G34: VENDREDI | H34: =+H27+1 -> 46248
C35: matin | F35: après-midi | I35: soir
B36: Personne | C36: entrée | D36: sortie | E36: durée | F36: entrée | G36: sortie | H36: durée | I36: entrée | J36: sortie | K36: durée | L36: durée total
A37: P515 | B37: JOHNNY | C37: 0.41666667 | D37: 0.58333333 | E37: =IF(D37>C37,D37-C37,C37-D37) -> 0.16666667 | H37: =IF(G37>F37,G37-F37,F37-G37) -> 0 | I37: 0.75 | J37: 0.91666667 | K37: =IF(J37>I37,J37-I37,I37-J37) -> 0.16666667 | L37: =E37+H37+K37 -> 0.33333333
A38: P524 | B38: CHRISTOPHE | C38: 0.41666667 | D38: 0.58333333 | E38: =IF(D38>C38,D38-C38,C38-D38) -> 0.16666667 | H38: =IF(G38>F38,G38-F38,F38-G38) -> 0 | I38: 0.75 | J38: 0.91666667 | K38: =IF(J38>I38,J38-I38,I38-J38) -> 0.16666667 | L38: =E38+H38+K38 -> 0.33333333
B39: DAUDET | E39: =IF(D39>C39,D39-C39,C39-D39) -> 0 | F39: 0.58333333 | G39: 0.75 | H39: =IF(G39>F39,G39-F39,F39-G39) -> 0.16666667 | I39: 0.75 | J39: 0.91666667 | K39: =IF(J39>I39,J39-I39,I39-J39) -> 0.16666667 | L39: =E39+H39+K39 -> 0.33333333
E40: =SUM(E37:E38) -> 0.33333333 | H40: =SUM(H37:H38) -> 0 | K40: =SUM(K37:K39) -> 0.5 | L40: =SUM(L37:L39) -> 1
C41: =+C34 -> CUISINE DETENTE | G41: SAMEDI | H41: =+H34+1 -> 46249
C42: matin | F42: après-midi | I42: soir
B43: Personne | C43: entrée | D43: sortie | E43: durée | F43: entrée | G43: sortie | H43: durée | I43: entrée | J43: sortie | K43: durée | L43: durée total
A44: P515 | B44: JOHNNY | C44: 0.41666667 | D44: 0.58333333 | E44: =IF(D44>C44,D44-C44,C44-D44) -> 0.16666667 | H44: =IF(G44>F44,G44-F44,F44-G44) -> 0 | I44: 0.75 | J44: 0.91666667 | K44: =IF(J44>I44,J44-I44,I44-J44) -> 0.16666667 | L44: =E44+H44+K44 -> 0.33333333
...

Sheet SALLE DETENTE
E2: EMPLOI DU TEMPS DETENTE WEEK 37
C5: SALLE DETENTE | G5: =+MAINTENANCE!G5 -> LUNDI | H5: =+MAINTENANCE!H5 -> 46244
C6: matin | F6: après-midi | I6: soir
B7: Personne | C7: entrée | D7: sortie | E7: durée | F7: entrée | G7: sortie | H7: durée | I7: entrée | J7: sortie | K7: durée | L7: durée total
A8: P331 | B8: JERRY | E8: =IF(D8>C8,D8-C8,C8-D8) -> 0 | H8: =IF(G8>F8,G8-F8,F8-G8) -> 0 | K8: =IF(J8>I8,J8-I8,I8-J8) -> 0 | L8: =E8+H8+K8 -> 0 | M8: REPOS
A9: P348 | B9: DENIS | E9: =IF(D9>C9,D9-C9,C9-D9) -> 0 | H9: =IF(G9>F9,G9-F9,F9-G9) -> 0 | K9: =IF(J9>I9,J9-I9,I9-J9) -> 0 | L9: =E9+H9+K9 -> 0
A10: P503 | B10: BRANDON | C10: 0.41666667 | D10: 0.5 | E10: =IF(D10>C10,D10-C10,C10-D10) -> 0.083333333 | F10: 0.5 | G10: 0.58333333 | H10: =IF(G10>F10,G10-F10,F10-G10) -> 0.083333333 | I10: 0.75 | J10: 0.91666667 | K10: =IF(J10>I10,J10-I10,I10-J10) -> 0.16666667 | L10: =E10+H10+K10 -> 0.33333333
A11: P518 | B11: LAZA | E11: =IF(D11>C11,D11-C11,C11-D11) -> 0 | F11: 0.58333333 | G11: 0.75 | H11: =IF(G11>F11,G11-F11,F11-G11) -> 0.16666667 | I11: 0.75 | J11: 0.91666667 | K11: =IF(J11>I11,J11-I11,I11-J11) -> 0.16666667 | L11: =E11+H11+K11 -> 0.33333333
A12: P538 | B12: ERICKA | E12: =IF(D12>C12,D12-C12,C12-D12) -> 0 | F12: 0.58333333 | G12: 0.75 | H12: =IF(G12>F12,G12-F12,F12-G12) -> 0.16666667 | I12: 0.75 | J12: 0.91666667 | K12: =IF(J12>I12,J12-I12,I12-J12) -> 0.16666667 | L12: =E12+H12+K12 -> 0.33333333
A13: P541 | B13: TATIANAH | C13: 0.25 | D13: 0.5 | E13: =IF(D13>C13,D13-C13,C13-D13) -> 0.25 | F13: 0.5 | G13: 0.58333333 | H13: =IF(G13>F13,G13-F13,F13-G13) -> 0.083333333 | K13: =IF(J13>I13,J13-I13,I13-J13) -> 0 | L13: =E13+H13+K13 -> 0.33333333
B14: KANTO | C14: 0.25 | D14: 0.5 | E14: =IF(D14>C14,D14-C14,C14-D14) -> 0.25 | F14: 0.5 | G14: 0.58333333 | H14: =IF(G14>F14,G14-F14,F14-G14) -> 0.083333333 | K14: =IF(J14>I14,J14-I14,I14-J14) -> 0 | L14: =E14+H14+K14 -> 0.33333333
B15: FANJA | C15: 0.41666667 | D15: 0.5 | E15: =IF(D15>C15,D15-C15,C15-D15) -> 0.083333333 | F15: 0.5 | G15: 0.58333333 | H15: =IF(G15>F15,G15-F15,F15-G15) -> 0.083333333 | I15: 0.75 | J15: 0.91666667 | K15: =IF(J15>I15,J15-I15,I15-J15) -> 0.16666667 | L15: =E15+H15+K15 -> 0.33333333
E16: =SUM(E8:E15) -> 0.66666667 | H16: =SUM(H8:H15) -> 0.66666667 | K16: =SUM(K8:K15) -> 0.66666667 | L16: =SUM(L8:L15) -> 2
C19: SALLE DETENTE | G19: MARDI | H19: =+H5+1 -> 46245
C20: matin | F20: après-midi | I20: soir
B21: Personne | C21: entrée | D21: sortie | E21: durée | F21: entrée | G21: sortie | H21: durée | I21: entrée | J21: sortie | K21: durée | L21: durée total
A22: P331 | B22: JERRY | C22: 0.25 | D22: 0.5 | E22: =IF(D22>C22,D22-C22,C22-D22) -> 0.25 | F22: 0.5 | G22: 0.58333333 | H22: =IF(G22>F22,G22-F22,F22-G22) -> 0.083333333 | I22: 0.75 | J22: 0.91666667 | K22: =IF(J22>I22,J22-I22,I22-J22) -> 0.16666667 | L22: =E22+H22+K22 -> 0.5
A23: P503 | B23: BRANDON | E23: =IF(D23>C23,D23-C23,C23-D23) -> 0 | F23: 0.58333333 | G23: 0.75 | H23: =IF(G23>F23,G23-F23,F23-G23) -> 0.16666667 | I23: 0.75 | J23: 0.91666667 | K23: =IF(J23>I23,J23-I23,I23-J23) -> 0.16666667 | L23: =E23+H23+K23 -> 0.33333333
A24: P518 | B24: LAZA | E24: =IF(D24>C24,D24-C24,C24-D24) -> 0 | H24: =IF(G24>F24,G24-F24,F24-G24) -> 0 | K24: =IF(J24>I24,J24-I24,I24-J24) -> 0 | L24: =E24+H24+K24 -> 0 | M24: REPOS
A25: P538 | B25: ERICKA | E25: =IF(D25>C25,D25-C25,C25-D25) -> 0 | F25: 0.58333333 | G25: 0.75 | H25: =IF(G25>F25,G25-F25,F25-G25) -> 0.16666667 | I25: 0.75 | J25: 0.91666667 | K25: =IF(J25>I25,J25-I25,I25-J25) -> 0.16666667 | L25: =E25+H25+K25 -> 0.33333333
A26: P541 | B26: TATIANAH | C26: 0.25 | D26: 0.5 | E26: =IF(D26>C26,D26-C26,C26-D26) -> 0.25 | F26: 0.5 | G26: 0.58333333 | H26: =IF(G26>F26,G26-F26,F26-G26) -> 0.083333333 | K26: =IF(J26>I26,J26-I26,I26-J26) -> 0 | L26: =E26+H26+K26 -> 0.33333333
A27: P457 | B27: LYDIA | E27: =IF(D27>C27,D27-C27,C27-D27) -> 0 | F27: 0.58333333 | G27: 0.75 | H27: =IF(G27>F27,G27-F27,F27-G27) -> 0.16666667 | I27: 0.75 | J27: 0.91666667 | K27: =IF(J27>I27,J27-I27,I27-J27) -> 0.16666667 | L27: =E27+H27+K27 -> 0.33333333
E28: =SUM(E22:E27) -> 0.5 | H28: =SUM(H22:H27) -> 0.66666667 | K28: =SUM(K22:K27) -> 0.66666667 | L28: =SUM(L22:L27) -> 1.8333333
C30: SALLE DETENTE | G30: MERCREDI | H30: =+H19+1 -> 46246
C31: matin | F31: après-midi | I31: soir
B32: Personne | C32: entrée | D32: sortie | E32: durée | F32: entrée | G32: sortie | H32: durée | I32: entrée | J32: sortie | K32: durée | L32: durée total
A33: P331 | B33: JERRY | C33: 0.41666667 | D33: 0.5 | E33: =IF(D33>C33,D33-C33,C33-D33) -> 0.083333333 | F33: 0.5 | G33: 0.75 | H33: =IF(G33>F33,G33-F33,F33-G33) -> 0.25 | I33: 0.75 | J33: 0.91666667 | K33: =IF(J33>I33,J33-I33,I33-J33) -> 0.16666667 | L33: =E33+H33+K33 -> 0.5
A34: P348 | B34: DENIS | E34: =IF(D34>C34,D34-C34,C34-D34) -> 0 | H34: =IF(G34>F34,G34-F34,F34-G34) -> 0 | K34: =IF(J34>I34,J34-I34,I34-J34) -> 0 | L34: =E34+H34+K34 -> 0
A35: P503 | B35: BRANDON | E35: =IF(D35>C35,D35-C35,C35-D35) -> 0 | H35: =IF(G35>F35,G35-F35,F35-G35) -> 0 | K35: =IF(J35>I35,J35-I35,I35-J35) -> 0 | L35: =E35+H35+K35 -> 0 | M35: REPOS
A36: P518 | B36: LAZA | C36: 0.25 | D36: 0.5 | E36: =IF(D36>C36,D36-C36,C36-D36) -> 0.25 | F36: 0.5 | G36: 0.58333333 | H36: =IF(G36>F36,G36-F36,F36-G36) -> 0.083333333 | K36: =IF(J36>I36,J36-I36,I36-J36) -> 0 | L36: =E36+H36+K36 -> 0.33333333
A37: P538 | B37: ERICKA | C37: 0.41666667 | D37: 0.5 | E37: =IF(D37>C37,D37-C37,C37-D37) -> 0.083333333 | F37: 0.5 | G37: 0.75 | H37: =IF(G37>F37,G37-F37,F37-G37) -> 0.25 | K37: =IF(J37>I37,J37-I37,I37-J37) -> 0 | L37: =E37+H37+K37 -> 0.33333333
A38: P541 | B38: TATIANAH | E38: =IF(D38>C38,D38-C38,C38-D38) -> 0 | F38: 0.58333333 | G38: 0.75 | H38: =IF(G38>F38,G38-F38,F38-G38) -> 0.16666667 | I38: 0.75 | J38: 0.91666667 | K38: =IF(J38>I38,J38-I38,I38-J38) -> 0.16666667 | L38: =E38+H38+K38 -> 0.33333333
B39: LYDIA | C39: 0.25 | D39: 0.5 | E39: =IF(D39>C39,D39-C39,C39-D39) -> 0.25 | F39: 0.5 | G39: 0.58333333 | H39: =IF(G39>F39,G39-F39,F39-G39) -> 0.083333333 | K39: =IF(J39>I39,J39-I39,I39-J39) -> 0 | L39: =E39+H39+K39 -> 0.33333333
B40: FANJA | E40: =IF(D40>C40,D40-C40,C40-D40) -> 0 | F40: 0.58333333 | G40: 0.75 | H40: =IF(G40>F40,G40-F40,F40-G40) -> 0.16666667 | I40: 0.75 | J40: 0.91666667 | K40: =IF(J40>I40,J40-I40,I40-J40) -> 0.16666667 | L40: =E40+H40+K40 -> 0.33333333
E41: =SUM(E33:E40) -> 0.66666667 | H41: =SUM(H33:H40) -> 1 | K41: =SUM(K33:K40) -> 0.5 | L41: =SUM(L33:L40) -> 2.1666667
C43: SALLE DETENTE | G43: JEUDI | H43: =+H30+1 -> 46247
C44: matin | F44: après-midi | I44: soir
B45: Personne | C45: entrée | D45: sortie | E45: durée | F45: entrée | G45: sortie | H45: durée | I45: entrée | J45: sortie | K45: durée | L45: durée total
A46: P331 | B46: JERRY | E46: =IF(D46>C46,D46-C46,C46-D46) -> 0 | F46: 0.58333333 | G46: 0.75 | H46: =IF(G46>F46,G46-F46,F46-G46) -> 0.16666667 | I46: 0.75 | J46: 0.91666667 | K46: =IF(J46>I46,J46-I46,I46-J46) -> 0.16666667 | L46: =E46+H46+K46 -> 0.33333333
A47: P348 | B47: DENIS | E47: =IF(D47>C47,D47-C47,C47-D47) -> 0 | H47: =IF(G47>F47,G47-F47,F47-G47) -> 0 | K47: =IF(J47>I47,J47-I47,I47-J47) -> 0 | L47: =E47+H47+K47 -> 0
...

Sheet CUISINE RESTO
E2: EMPLOI DU TEMPS CUISINE RESTO WEEK 36
C5: CUISINE RESTO | G5: =+MAINTENANCE!G5 -> LUNDI | H5: =+'CUISINE DETENTE'!H5 -> 46244
C6: matin | F6: après-midi | I6: soir
B7: Personne | C7: entrée | D7: sortie | E7: durée | F7: entrée | G7: sortie | H7: durée | I7: entrée | J7: sortie | K7: durée | L7: durée total
A8: P525 | B8: ANJARA | C8: 0.41666667 | D8: 0.58333333 | E8: =IF(D8>C8,D8-C8,C8-D8) -> 0.16666667 | H8: =IF(G8>F8,G8-F8,F8-G8) -> 0 | I8: 0.75 | J8: 0.91666667 | K8: =IF(J8>I8,J8-I8,I8-J8) -> 0.16666667 | L8: =E8+H8+K8 -> 0.33333333
A9: P545 | B9: CELESTIN | C9: 0.25 | D9: 0.5 | E9: =IF(D9>C9,D9-C9,C9-D9) -> 0.25 | F9: 0.5 | G9: 0.58333333 | H9: =IF(G9>F9,G9-F9,F9-G9) -> 0.083333333 | K9: =IF(J9>I9,J9-I9,I9-J9) -> 0 | L9: =E9+H9+K9 -> 0.33333333
A10: P441 | B10: CHRISTIAN | E10: =IF(D10>C10,D10-C10,C10-D10) -> 0 | F10: 0.58333333 | G10: 0.75 | H10: =IF(G10>F10,G10-F10,F10-G10) -> 0.16666667 | I10: 0.75 | J10: 0.91666667 | K10: =IF(J10>I10,J10-I10,I10-J10) -> 0.16666667 | L10: =E10+H10+K10 -> 0.33333333
A11: P439 | B11: HERY | E11: =IF(D11>C11,D11-C11,C11-D11) -> 0 | H11: =IF(G11>F11,G11-F11,F11-G11) -> 0 | K11: =IF(J11>I11,J11-I11,I11-J11) -> 0 | L11: =E11+H11+K11 -> 0 | M11: REPOS
A12: P542 | B12: JEAN JACQUES | E12: =IF(D12>C12,D12-C12,C12-D12) -> 0 | H12: =IF(G12>F12,G12-F12,F12-G12) -> 0 | K12: =IF(J12>I12,J12-I12,I12-J12) -> 0 | L12: =E12+H12+K12 -> 0 | M12: REPOS
A13: P501 | B13: PATRICK | E13: =IF(D13>C13,D13-C13,C13-D13) -> 0 | F13: 0.58333333 | G13: 0.75 | H13: =IF(G13>F13,G13-F13,F13-G13) -> 0.16666667 | I13: 0.75 | J13: 0.91666667 | K13: =IF(J13>I13,J13-I13,I13-J13) -> 0.16666667 | L13: =E13+H13+K13 -> 0.33333333
A14: P461 | B14: SAFIDY | E14: =IF(D14>C14,D14-C14,C14-D14) -> 0 | H14: =IF(G14>F14,G14-F14,F14-G14) -> 0 | K14: =IF(J14>I14,J14-I14,I14-J14) -> 0 | L14: =E14+H14+K14 -> 0 | M14: REPOS
A15: P268 | B15: ROLAND | C15: 0.25 | D15: 0.5 | E15: =IF(D15>C15,D15-C15,C15-D15) -> 0.25 | F15: 0.5 | G15: 0.58333333 | H15: =IF(G15>F15,G15-F15,F15-G15) -> 0.083333333 | K15: =IF(J15>I15,J15-I15,I15-J15) -> 0 | L15: =E15+H15+K15 -> 0.33333333
A16: P411 | B16: TOLOTRA | C16: 0.41666667 | D16: 0.58333333 | E16: =IF(D16>C16,D16-C16,C16-D16) -> 0.16666667 | H16: =IF(G16>F16,G16-F16,F16-G16) -> 0 | I16: 0.75 | J16: 0.91666667 | K16: =IF(J16>I16,J16-I16,I16-J16) -> 0.16666667 | L16: =E16+H16+K16 -> 0.33333333
A17: P449 | B17: TSILAVINA | C17: 0.25 | D17: 0.5 | E17: =IF(D17>C17,D17-C17,C17-D17) -> 0.25 | F17: 0.5 | G17: 0.58333333 | H17: =IF(G17>F17,G17-F17,F17-G17) -> 0.083333333 | K17: =IF(J17>I17,J17-I17,I17-J17) -> 0 | L17: =E17+H17+K17 -> 0.33333333
A18: P546 | B18: XAVIER | C18: 0.41666667 | D18: 0.58333333 | E18: =IF(D18>C18,D18-C18,C18-D18) -> 0.16666667 | H18: =IF(G18>F18,G18-F18,F18-G18) -> 0 | I18: 0.75 | J18: 0.91666667 | K18: =IF(J18>I18,J18-I18,I18-J18) -> 0.16666667 | L18: =E18+H18+K18 -> 0.33333333
A19: Stagiaire | B19: TOKY | C19: 0.41666667 | D19: 0.58333333 | E19: =IF(D19>C19,D19-C19,C19-D19) -> 0.16666667 | H19: =IF(G19>F19,G19-F19,F19-G19) -> 0 | I19: 0.75 | J19: 0.91666667 | K19: =IF(J19>I19,J19-I19,I19-J19) -> 0.16666667 | L19: =E19+H19+K19 -> 0.33333333
A20: Stagiaire | B20: NANJA | E20: =IF(D20>C20,D20-C20,C20-D20) -> 0 | H20: =IF(G20>F20,G20-F20,F20-G20) -> 0 | K20: =IF(J20>I20,J20-I20,I20-J20) -> 0 | L20: =E20+H20+K20 -> 0 | M20: REPOS
E21: =SUM(E8:E20) -> 1.4166667 | H21: =SUM(H8:H20) -> 0.58333333 | K21: =SUM(K8:K20) -> 1 | L21: =SUM(L8:L20) -> 3
C23: =+C5 -> CUISINE RESTO | G23: MARDI | H23: =+H5+1 -> 46245
C24: matin | F24: après-midi | I24: soir
B25: Personne | C25: entrée | D25: sortie | E25: durée | F25: entrée | G25: sortie | H25: durée | I25: entrée | J25: sortie | K25: durée | L25: durée total
A26: P525 | B26: ANJARA | E26: =IF(D26>C26,D26-C26,C26-D26) -> 0 | H26: =IF(G26>F26,G26-F26,F26-G26) -> 0 | K26: =IF(J26>I26,J26-I26,I26-J26) -> 0 | L26: =E26+H26+K26 -> 0 | M26: REPOS
A27: P545 | B27: CELESTIN | E27: =IF(D27>C27,D27-C27,C27-D27) -> 0 | H27: =IF(G27>F27,G27-F27,F27-G27) -> 0 | K27: =IF(J27>I27,J27-I27,I27-J27) -> 0 | L27: =E27+H27+K27 -> 0 | M27: REPOS
A28: P441 | B28: CHRISTIAN | E28: =IF(D28>C28,D28-C28,C28-D28) -> 0 | F28: 0.58333333 | G28: 0.75 | H28: =IF(G28>F28,G28-F28,F28-G28) -> 0.16666667 | I28: 0.75 | J28: 0.91666667 | K28: =IF(J28>I28,J28-I28,I28-J28) -> 0.16666667 | L28: =E28+H28+K28 -> 0.33333333
A29: P439 | B29: HERY | C29: 0.25 | D29: 0.5 | E29: =IF(D29>C29,D29-C29,C29-D29) -> 0.25 | F29: 0.5 | G29: 0.58333333 | H29: =IF(G29>F29,G29-F29,F29-G29) -> 0.083333333 | K29: =IF(J29>I29,J29-I29,I29-J29) -> 0 | L29: =E29+H29+K29 -> 0.33333333
A30: P542 | B30: JEAN JACQUES | C30: 0.25 | D30: 0.5 | E30: =IF(D30>C30,D30-C30,C30-D30) -> 0.25 | F30: 0.5 | G30: 0.58333333 | H30: =IF(G30>F30,G30-F30,F30-G30) -> 0.083333333 | K30: =IF(J30>I30,J30-I30,I30-J30) -> 0 | L30: =E30+H30+K30 -> 0.33333333
A31: P501 | B31: PATRICK | C31: 0.41666667 | D31: 0.58333333 | E31: =IF(D31>C31,D31-C31,C31-D31) -> 0.16666667 | H31: =IF(G31>F31,G31-F31,F31-G31) -> 0 | I31: 0.75 | J31: 0.91666667 | K31: =IF(J31>I31,J31-I31,I31-J31) -> 0.16666667 | L31: =E31+H31+K31 -> 0.33333333
A32: P461 | B32: SAFIDY | C32: 0.25 | D32: 0.5 | E32: =IF(D32>C32,D32-C32,C32-D32) -> 0.25 | F32: 0.5 | G32: 0.58333333 | H32: =IF(G32>F32,G32-F32,F32-G32) -> 0.083333333 | K32: =IF(J32>I32,J32-I32,I32-J32) -> 0 | L32: =E32+H32+K32 -> 0.33333333
A33: P268 | B33: ROLAND | C33: 0.25 | D33: 0.5 | E33: =IF(D33>C33,D33-C33,C33-D33) -> 0.25 | F33: 0.5 | G33: 0.58333333 | H33: =IF(G33>F33,G33-F33,F33-G33) -> 0.083333333 | K33: =IF(J33>I33,J33-I33,I33-J33) -> 0 | L33: =E33+H33+K33 -> 0.33333333
A34: P411 | B34: TOLOTRA | C34: 0.41666667 | D34: 0.58333333 | E34: =IF(D34>C34,D34-C34,C34-D34) -> 0.16666667 | H34: =IF(G34>F34,G34-F34,F34-G34) -> 0 | I34: 0.75 | J34: 0.91666667 | K34: =IF(J34>I34,J34-I34,I34-J34) -> 0.16666667 | L34: =E34+H34+K34 -> 0.33333333
A35: P449 | B35: TSILAVINA | E35: =IF(D35>C35,D35-C35,C35-D35) -> 0 | H35: =IF(G35>F35,G35-F35,F35-G35) -> 0 | K35: =IF(J35>I35,J35-I35,I35-J35) -> 0 | L35: =E35+H35+K35 -> 0 | M35: REPOS
A36: P546 | B36: XAVIER | E36: =IF(D36>C36,D36-C36,C36-D36) -> 0 | F36: 0.58333333 | G36: 0.75 | H36: =IF(G36>F36,G36-F36,F36-G36) -> 0.16666667 | I36: 0.75 | J36: 0.91666667 | K36: =IF(J36>I36,J36-I36,I36-J36) -> 0.16666667 | L36: =E36+H36+K36 -> 0.33333333
A37: Stagiaire | B37: TOKY | E37: =IF(D37>C37,D37-C37,C37-D37) -> 0 | F37: 0.58333333 | G37: 0.75 | H37: =IF(G37>F37,G37-F37,F37-G37) -> 0.16666667 | I37: 0.75 | J37: 0.91666667 | K37: =IF(J37>I37,J37-I37,I37-J37) -> 0.16666667 | L37: =E37+H37+K37 -> 0.33333333
A38: Stagiaire | B38: NANJA | C38: 0.41666667 | D38: 0.58333333 | E38: =IF(D38>C38,D38-C38,C38-D38) -> 0.16666667 | H38: =IF(G38>F38,G38-F38,F38-G38) -> 0 | I38: 0.75 | J38: 0.91666667 | K38: =IF(J38>I38,J38-I38,I38-J38) -> 0.16666667 | L38: =E38+H38+K38 -> 0.33333333
E39: =SUM(E26:E38) -> 1.5 | H39: =SUM(H26:H38) -> 0.83333333 | K39: =SUM(K26:K38) -> 1 | L39: =SUM(L26:L38) -> 3.3333333
C41: =+C23 -> CUISINE RESTO | G41: MERCREDI | H41: =+H23+1 -> 46246
C42: matin | F42: après-midi | I42: soir
B43: Personne | C43: entrée | D43: sortie | E43: durée | F43: entrée | G43: sortie | H43: durée | I43: entrée | J43: sortie | K43: durée | L43: durée total
A44: P525 | B44: ANJARA | E44: =IF(D44>C44,D44-C44,C44-D44) -> 0 | F44: 0.58333333 | G44: 0.75 | H44: =IF(G44>F44,G44-F44,F44-G44) -> 0.16666667 | I44: 0.75 | J44: 0.91666667 | K44: =IF(J44>I44,J44-I44,I44-J44) -> 0.16666667 | L44: =E44+H44+K44 -> 0.33333333
A45: P545 | B45: CELESTIN | C45: 0.25 | D45: 0.5 | E45: =IF(D45>C45,D45-C45,C45-D45) -> 0.25 | F45: 0.5 | G45: 0.58333333 | H45: =IF(G45>F45,G45-F45,F45-G45) -> 0.083333333 | K45: =IF(J45>I45,J45-I45,I45-J45) -> 0 | L45: =E45+H45+K45 -> 0.33333333
...

Sheet PLONGE
E2: EMPLOI DU TEMPS PLONGE WEEK 37
C5: PLONGE | G5: LUNDI | H5: =+SECURITE!H5 -> 46244
C6: matin | F6: après-midi | I6: soir
B7: Personne | C7: entrée | D7: sortie | E7: durée | F7: entrée | G7: sortie | H7: durée | I7: entrée | J7: sortie | K7: durée | L7: durée total
A8: P451 | B8: TAHIRY | E8: =IF(D8>C8,D8-C8,C8-D8) -> 0 | H8: =IF(G8>F8,G8-F8,F8-G8) -> 0 | K8: =IF(J8>I8,J8-I8,I8-J8) -> 0 | L8: =E8+H8+K8 -> 0 | M8: REPOS
A9: P466 | B9: HANITRA | E9: =IF(D9>C9,D9-C9,C9-D9) -> 0 | F9: 0.58333333 | G9: 0.75 | H9: =IF(G9>F9,G9-F9,F9-G9) -> 0.16666667 | I9: 0.75 | J9: 0.91666667 | K9: =IF(J9>I9,J9-I9,I9-J9) -> 0.16666667 | L9: =E9+H9+K9 -> 0.33333333
A10: P486 | B10: PAULETTE | C10: 0.25 | D10: 0.5 | E10: =IF(D10>C10,D10-C10,C10-D10) -> 0.25 | F10: 0.5 | G10: 0.58333333 | H10: =IF(G10>F10,G10-F10,F10-G10) -> 0.083333333 | K10: =IF(J10>I10,J10-I10,I10-J10) -> 0 | L10: =E10+H10+K10 -> 0.33333333
A11: P476 | B11: VANULIE | C11: 0.25 | D11: 0.5 | E11: =IF(D11>C11,D11-C11,C11-D11) -> 0.25 | F11: 0.5 | G11: 0.58333333 | H11: =IF(G11>F11,G11-F11,F11-G11) -> 0.083333333 | K11: =IF(J11>I11,J11-I11,I11-J11) -> 0 | L11: =E11+H11+K11 -> 0.33333333
A12: P455 | B12: NIRY | C12: 0.25 | D12: 0.41666667 | E12: =IF(D12>C12,D12-C12,C12-D12) -> 0.16666667 | H12: =IF(G12>F12,G12-F12,F12-G12) -> 0 | I12: 0.75 | J12: 0.91666667 | K12: =IF(J12>I12,J12-I12,I12-J12) -> 0.16666667 | L12: =E12+H12+K12 -> 0.33333333
A13: P544 | B13: MARIO | E13: =IF(D13>C13,D13-C13,C13-D13) -> 0 | F13: 0.58333333 | G13: 0.75 | H13: =IF(G13>F13,G13-F13,F13-G13) -> 0.16666667 | I13: 0.75 | J13: 0.91666667 | K13: =IF(J13>I13,J13-I13,I13-J13) -> 0.16666667 | L13: =E13+H13+K13 -> 0.33333333
E14: =SUM(E8:E13) -> 0.66666667 | H14: =SUM(H8:H13) -> 0.5 | K14: =SUM(K8:K13) -> 0.5 | L14: =SUM(L8:L13) -> 1.6666667
C16: PLONGE | G16: MARDI | H16: =+H5+1 -> 46245
C17: matin | F17: après-midi | I17: soir
B18: Personne | C18: entrée | D18: sortie | E18: durée | F18: entrée | G18: sortie | H18: durée | I18: entrée | J18: sortie | K18: durée | L18: durée total
A19: P451 | B19: TAHIRY | E19: =IF(D19>C19,D19-C19,C19-D19) -> 0 | F19: 0.58333333 | G19: 0.75 | H19: =IF(G19>F19,G19-F19,F19-G19) -> 0.16666667 | I19: 0.75 | J19: 0.91666667 | K19: =IF(J19>I19,J19-I19,I19-J19) -> 0.16666667 | L19: =E19+H19+K19 -> 0.33333333
A20: P466 | B20: HANITRA | E20: =IF(D20>C20,D20-C20,C20-D20) -> 0 | F20: 0.58333333 | G20: 0.75 | H20: =IF(G20>F20,G20-F20,F20-G20) -> 0.16666667 | I20: 0.75 | J20: 0.91666667 | K20: =IF(J20>I20,J20-I20,I20-J20) -> 0.16666667 | L20: =E20+H20+K20 -> 0.33333333
A21: P486 | B21: PAULETTE | C21: 0.25 | D21: 0.5 | E21: =IF(D21>C21,D21-C21,C21-D21) -> 0.25 | F21: 0.5 | G21: 0.58333333 | H21: =IF(G21>F21,G21-F21,F21-G21) -> 0.083333333 | K21: =IF(J21>I21,J21-I21,I21-J21) -> 0 | L21: =E21+H21+K21 -> 0.33333333
A22: P476 | B22: VANILIE | E22: =IF(D22>C22,D22-C22,C22-D22) -> 0 | H22: =IF(G22>F22,G22-F22,F22-G22) -> 0 | K22: =IF(J22>I22,J22-I22,I22-J22) -> 0 | L22: =E22+H22+K22 -> 0 | M22: REPOS
A23: P455 | B23: NIRY | C23: 0.25 | D23: 0.5 | E23: =IF(D23>C23,D23-C23,C23-D23) -> 0.25 | F23: 0.5 | G23: 0.58333333 | H23: =IF(G23>F23,G23-F23,F23-G23) -> 0.083333333 | K23: =IF(J23>I23,J23-I23,I23-J23) -> 0 | L23: =E23+H23+K23 -> 0.33333333
A24: P544 | B24: MARIO | C24: 0.25 | D24: 0.41666667 | E24: =IF(D24>C24,D24-C24,C24-D24) -> 0.16666667 | H24: =IF(G24>F24,G24-F24,F24-G24) -> 0 | I24: 0.75 | J24: 0.91666667 | K24: =IF(J24>I24,J24-I24,I24-J24) -> 0.16666667 | L24: =E24+H24+K24 -> 0.33333333
E25: =SUM(E19:E23) -> 0.5 | H25: =SUM(H19:H24) -> 0.5 | K25: =SUM(K19:K24) -> 0.5 | L25: =SUM(L19:L24) -> 1.6666667
C27: PLONGE | G27: MERCREDI | H27: =+H16+1 -> 46246
C28: matin | F28: après-midi | I28: soir
B29: Personne | C29: entrée | D29: sortie | E29: durée | F29: entrée | G29: sortie | H29: durée | I29: entrée | J29: sortie | K29: durée | L29: durée total
A30: P451 | B30: TAHIRY | E30: =IF(D30>C30,D30-C30,C30-D30) -> 0 | F30: 0.58333333 | G30: 0.75 | H30: =IF(G30>F30,G30-F30,F30-G30) -> 0.16666667 | I30: 0.75 | J30: 0.91666667 | K30: =IF(J30>I30,J30-I30,I30-J30) -> 0.16666667 | L30: =E30+H30+K30 -> 0.33333333
A31: P466 | B31: HANITRA | C31: 0.25 | D31: 0.41666667 | E31: =IF(D31>C31,D31-C31,C31-D31) -> 0.16666667 | H31: =IF(G31>F31,G31-F31,F31-G31) -> 0 | I31: 0.75 | J31: 0.91666667 | K31: =IF(J31>I31,J31-I31,I31-J31) -> 0.16666667 | L31: =E31+H31+K31 -> 0.33333333
A32: P486 | B32: PAULETTE | E32: =IF(D32>C32,D32-C32,C32-D32) -> 0 | H32: =IF(G32>F32,G32-F32,F32-G32) -> 0 | K32: =IF(J32>I32,J32-I32,I32-J32) -> 0 | L32: =E32+H32+K32 -> 0 | M32: REPOS
A33: P476 | B33: VANULIE | C33: 0.25 | D33: 0.5 | E33: =IF(D33>C33,D33-C33,C33-D33) -> 0.25 | F33: 0.5 | G33: 0.58333333 | H33: =IF(G33>F33,G33-F33,F33-G33) -> 0.083333333 | K33: =IF(J33>I33,J33-I33,I33-J33) -> 0 | L33: =E33+H33+K33 -> 0.33333333
A34: P455 | B34: NIRY | C34: 0.25 | D34: 0.5 | E34: =IF(D34>C34,D34-C34,C34-D34) -> 0.25 | F34: 0.5 | G34: 0.58333333 | H34: =IF(G34>F34,G34-F34,F34-G34) -> 0.083333333 | K34: =IF(J34>I34,J34-I34,I34-J34) -> 0 | L34: =E34+H34+K34 -> 0.33333333
A35: P544 | B35: MARIO | E35: =IF(D35>C35,D35-C35,C35-D35) -> 0 | F35: 0.58333333 | G35: 0.75 | H35: =IF(G35>F35,G35-F35,F35-G35) -> 0.16666667 | I35: 0.75 | J35: 0.91666667 | K35: =IF(J35>I35,J35-I35,I35-J35) -> 0.16666667 | L35: =E35+H35+K35 -> 0.33333333
E36: =SUM(E30:E35) -> 0.66666667 | H36: =SUM(H30:H35) -> 0.5 | K36: =SUM(K30:K35) -> 0.5 | L36: =SUM(L30:L35) -> 1.6666667
C38: PLONGE | G38: JEUDI | H38: =+H27+1 -> 46247
C39: matin | F39: après-midi | I39: soir
B40: Personne | C40: entrée | D40: sortie | E40: durée | F40: entrée | G40: sortie | H40: durée | I40: entrée | J40: sortie | K40: durée | L40: durée total
A41: P451 | B41: TAHIRY | E41: =IF(D41>C41,D41-C41,C41-D41) -> 0 | F41: 0.58333333 | G41: 0.75 | H41: =IF(G41>F41,G41-F41,F41-G41) -> 0.16666667 | I41: 0.75 | J41: 0.91666667 | K41: =IF(J41>I41,J41-I41,I41-J41) -> 0.16666667 | L41: =E41+H41+K41 -> 0.33333333
A42: P466 | B42: HANITRA | E42: =IF(D42>C42,D42-C42,C42-D42) -> 0 | F42: 0.58333333 | G42: 0.75 | H42: =IF(G42>F42,G42-F42,F42-G42) -> 0.16666667 | I42: 0.75 | J42: 0.91666667 | K42: =IF(J42>I42,J42-I42,I42-J42) -> 0.16666667 | L42: =E42+H42+K42 -> 0.33333333
A43: P486 | B43: PAULETTE | C43: 0.25 | D43: 0.5 | E43: =IF(D43>C43,D43-C43,C43-D43) -> 0.25 | F43: 0.5 | G43: 0.58333333 | H43: =IF(G43>F43,G43-F43,F43-G43) -> 0.083333333 | K43: =IF(J43>I43,J43-I43,I43-J43) -> 0 | L43: =E43+H43+K43 -> 0.33333333
A44: P476 | B44: VANULIE | C44: 0.25 | D44: 0.41666667 | E44: =IF(D44>C44,D44-C44,C44-D44) -> 0.16666667 | H44: =IF(G44>F44,G44-F44,F44-G44) -> 0 | I44: 0.75 | J44: 0.91666667 | K44: =IF(J44>I44,J44-I44,I44-J44) -> 0.16666667 | L44: =E44+H44+K44 -> 0.33333333
A45: P455 | B45: NIRY | C45: 0.25 | D45: 0.5 | E45: =IF(D45>C45,D45-C45,C45-D45) -> 0.25 | F45: 0.5 | G45: 0.58333333 | H45: =IF(G45>F45,G45-F45,F45-G45) -> 0.083333333 | K45: =IF(J45>I45,J45-I45,I45-J45) -> 0 | L45: =E45+H45+K45 -> 0.33333333
A46: P544 | B46: MARIO | E46: =IF(D46>C46,D46-C46,C46-D46) -> 0 | H46: =IF(G46>F46,G46-F46,F46-G46) -> 0 | K46: =IF(J46>I46,J46-I46,I46-J46) -> 0 | L46: =E46+H46+K46 -> 0 | M46: REPOS
...

Sheet SALLE RESTO
E2: EMPLOI DU TEMPS SALLE RESTO WEEK 37
C5: SALLE SNACK | G5: LUNDI | H5: =+SECURITE!H5 -> 46244
C6: matin | F6: après-midi | I6: soir
B7: Personne | C7: entrée | D7: sortie | E7: durée | F7: entrée | G7: sortie | H7: durée | I7: entrée | J7: sortie | K7: durée | L7: durée total
A8: P447 | B8: BABY | E8: =IF(D8>C8,D8-C8,C8-D8) -> 0 | F8: 0.58333333 | G8: 0.75 | H8: =IF(G8>F8,G8-F8,F8-G8) -> 0.16666667 | I8: 0.75 | J8: 0.91666667 | K8: =IF(J8>I8,J8-I8,I8-J8) -> 0.16666667 | L8: =E8+H8+K8 -> 0.33333333
A9: P185 | B9: EUGENIE | C9: 0.25 | D9: 0.41666667 | E9: =IF(D9>C9,D9-C9,C9-D9) -> 0.16666667 | H9: =IF(G9>F9,G9-F9,F9-G9) -> 0 | I9: 0.75 | J9: 0.91666667 | K9: =IF(J9>I9,J9-I9,I9-J9) -> 0.16666667 | L9: =E9+H9+K9 -> 0.33333333
A10: P042 | B10: FANJA | E10: =IF(D10>C10,D10-C10,C10-D10) -> 0 | F10: 0.58333333 | G10: 0.75 | H10: =IF(G10>F10,G10-F10,F10-G10) -> 0.16666667 | I10: 0.75 | J10: 0.91666667 | K10: =IF(J10>I10,J10-I10,I10-J10) -> 0.16666667 | L10: =E10+H10+K10 -> 0.33333333
A11: P185 | B11: LANDRY | E11: =IF(D11>C11,D11-C11,C11-D11) -> 0 | H11: =IF(G11>F11,G11-F11,F11-G11) -> 0 | K11: =IF(J11>I11,J11-I11,I11-J11) -> 0 | L11: =E11+H11+K11 -> 0 | M11: REPOS
A12: P457 | B12: LYDIA | E12: =IF(D12>C12,D12-C12,C12-D12) -> 0 | F12: 0.58333333 | G12: 0.75 | H12: =IF(G12>F12,G12-F12,F12-G12) -> 0.16666667 | I12: 0.75 | J12: 0.91666667 | K12: =IF(J12>I12,J12-I12,I12-J12) -> 0.16666667 | L12: =E12+H12+K12 -> 0.33333333
A13: P358 | B13: RHODIE | C13: 0.25 | D13: 0.5 | E13: =IF(D13>C13,D13-C13,C13-D13) -> 0.25 | F13: 0.5 | G13: 0.58333333 | H13: =IF(G13>F13,G13-F13,F13-G13) -> 0.083333333 | K13: =IF(J13>I13,J13-I13,I13-J13) -> 0 | L13: =E13+H13+K13 -> 0.33333333
A14: P507 | B14: NOMENA | E14: =IF(D14>C14,D14-C14,C14-D14) -> 0 | H14: =IF(G14>F14,G14-F14,F14-G14) -> 0 | K14: =IF(J14>I14,J14-I14,I14-J14) -> 0 | L14: =E14+H14+K14 -> 0 | M14: REPOS
A15: P180 | B15: VOAHANGY | C15: 0.25 | D15: 0.5 | E15: =IF(D15>C15,D15-C15,C15-D15) -> 0.25 | F15: 0.5 | G15: 0.58333333 | H15: =IF(G15>F15,G15-F15,F15-G15) -> 0.083333333 | K15: =IF(J15>I15,J15-I15,I15-J15) -> 0 | L15: =E15+H15+K15 -> 0.33333333
A16: P537 | B16: TOKY | C16: 0.25 | D16: 0.41666667 | E16: =IF(D16>C16,D16-C16,C16-D16) -> 0.16666667 | H16: =IF(G16>F16,G16-F16,F16-G16) -> 0 | I16: 0.75 | J16: 0.91666667 | K16: =IF(J16>I16,J16-I16,I16-J16) -> 0.16666667 | L16: =E16+H16+K16 -> 0.33333333
B17: ALAIN | C17: 0.25 | D17: 0.5 | E17: =IF(D17>C17,D17-C17,C17-D17) -> 0.25 | F17: 0.5 | G17: 0.58333333 | H17: =IF(G17>F17,G17-F17,F17-G17) -> 0.083333333 | K17: =IF(J17>I17,J17-I17,I17-J17) -> 0 | L17: =E17+H17+K17 -> 0.33333333
B18: FRANCIA | E18: =IF(D18>C18,D18-C18,C18-D18) -> 0 | H18: =IF(G18>F18,G18-F18,F18-G18) -> 0 | K18: =IF(J18>I18,J18-I18,I18-J18) -> 0 | L18: =E18+H18+K18 -> 0
A19: N | B19: NIAVO | C19: 0.25 | D19: 0.5 | E19: =IF(D19>C19,D19-C19,C19-D19) -> 0.25 | F19: 0.5 | G19: 0.58333333 | H19: =IF(G19>F19,G19-F19,F19-G19) -> 0.083333333 | K19: =IF(J19>I19,J19-I19,I19-J19) -> 0 | L19: =E19+H19+K19 -> 0.33333333
E20: =SUM(E8:E19) -> 1.3333333 | H20: =SUM(H8:H19) -> 0.83333333 | K20: =SUM(K8:K19) -> 0.83333333 | L20: =SUM(L8:L19) -> 3
C22: SALLE SNACK | G22: MARDI | H22: =+H5+1 -> 46245
C23: matin | F23: après-midi | I23: soir
B24: Personne | C24: entrée | D24: sortie | E24: durée | F24: entrée | G24: sortie | H24: durée | I24: entrée | J24: sortie | K24: durée | L24: durée total
A25: P447 | B25: BABY | E25: =IF(D25>C25,D25-C25,C25-D25) -> 0 | F25: 0.58333333 | G25: 0.75 | H25: =IF(G25>F25,G25-F25,F25-G25) -> 0.16666667 | I25: 0.75 | J25: 0.91666667 | K25: =IF(J25>I25,J25-I25,I25-J25) -> 0.16666667 | L25: =E25+H25+K25 -> 0.33333333
A26: P185 | B26: EUGENIE | C26: 0.41666667 | D26: 0.58333333 | E26: =IF(D26>C26,D26-C26,C26-D26) -> 0.16666667 | H26: =IF(G26>F26,G26-F26,F26-G26) -> 0 | I26: 0.75 | J26: 0.91666667 | K26: =IF(J26>I26,J26-I26,I26-J26) -> 0.16666667 | L26: =E26+H26+K26 -> 0.33333333
A27: P042 | B27: FANJA | E27: =IF(D27>C27,D27-C27,C27-D27) -> 0 | H27: =IF(G27>F27,G27-F27,F27-G27) -> 0 | K27: =IF(J27>I27,J27-I27,I27-J27) -> 0 | L27: =E27+H27+K27 -> 0 | M27: REPOS
A28: P185 | B28: LANDRY | E28: =IF(D28>C28,D28-C28,C28-D28) -> 0 | F28: 0.58333333 | G28: 0.75 | H28: =IF(G28>F28,G28-F28,F28-G28) -> 0.16666667 | I28: 0.75 | J28: 0.91666667 | K28: =IF(J28>I28,J28-I28,I28-J28) -> 0.16666667 | L28: =E28+H28+K28 -> 0.33333333
A29: P358 | B29: RHODIE | C29: 0.25 | D29: 0.41666667 | E29: =IF(D29>C29,D29-C29,C29-D29) -> 0.16666667 | H29: =IF(G29>F29,G29-F29,F29-G29) -> 0 | I29: 0.75 | J29: 0.91666667 | K29: =IF(J29>I29,J29-I29,I29-J29) -> 0.16666667 | L29: =E29+H29+K29 -> 0.33333333
